# 异常处理

## try catch

[trycatch 不能捕获运行时异常_面试官：用一句话描述 JS 异常是否能被 try catch 捕获到 ?... - 掘金 (juejin.cn)](https://juejin.cn/post/7021889887615844360?utm_source=gold_browser_extension)

1. 只能捕获运行时错误，不能捕获语法错误
   TODO：js解析运行原理

2. 异步无法捕获

   - 一般异步

     ```js
     try{
         setTimeout(()=>{
              console.log(a.b);  
         }, 100)
     }catch(e){
         console.log('error',e);
     }
     console.log(111);
     //output
     111
     Uncaught ReferenceError: a is not defined
     ```

     评论区有问setTimeout中错误除了用window.onerror有没有别的方法捕获，查了下，除了在回调内部用try..catch，是没有别的办法的（他们在setTimeout前面加await的写法是错误的，小声bb）

   - promise

     ```js
     try {
     	new Promise(() => {
     		throw new Error('new promise throw error');
     	});
     } catch (error) {
     	console.log(error);
     }
     //output
     Uncaught (in promise) Error: new promise throw error
     ```

     评论区有人提到promise内是同步代码，为什么不能捕获？

     [Error handling with promises (javascript.info)](https://javascript.info/promise-error-handling)The Modern JavaScript Tutorial提到promise有隐式的try..catch，会将error转化为rejected promise，变成了异步代码，因此不能捕获

     > The code of a promise executor and promise handlers has an "invisible `try..catch`" around it. If an exception happens, it gets caught and treated as a rejection.

     ```js
     new Promise((resolve, reject) => {
       throw new Error("Whoops!");
     }).catch(alert); // Error: Whoops!
     
     //Works exactly the same as this:
     new Promise((resolve, reject) => {
       reject(new Error("Whoops!"));
     }).catch(alert); // Error: Whoops!
     ```
